Workbook

Sheet List of Tables
A1: Temporary Assistance for Needy Families (TANF)
A2: Caseload Data - Fiscal Year (FY) 2024
A3: LIST OF TABLES
A4: Families
A5: TANF: Total Number of Families
A6: TANF: Total Number of Two Parent Families
A7: TANF: Total Number of One Parent Families
A8: TANF: Total Number of No Parent Families
A9: Recipients
A10: TANF: Total Number of Recipients
A11: TANF: Total Number of Adult Recipients
A12: TANF: Total Number of Child Recipients
... A28: Average Monthly Number of Recipients

Sheet TFam
A1: TANF: Total Number of Families
A2: Fiscal Year 2024
A3: 45687
A4: State | B4: 45200 | C4: 45231 | D4: 45261 | E4: 45292 | F4: 45323 | G4: 45352 | H4: 45383 | I4: 45413 | J4: 45444 | K4: 45474 | L4: 45505 | M4: 45536 | N4: Average FY 2024
A5: U.S. Totals | B5: =SUM(B6:B59) -> 856530 | C5: =SUM(C6:C59) -> 838009 | D5: =SUM(D6:D59) -> 827000 | E5: =SUM(E6:E59) -> 826530 | F5: =SUM(F6:F59) -> 829092 | G5: =SUM(G6:G59) -> 829625 | H5: =SUM(H6:H59) -> 830038 | I5: =SUM(I6:I59) -> 835567 | ... M5: =SUM(M6:M59) -> 861564 | N5: =AVERAGE(B5:M5) -> 841208.67
A6: Alabama | B6: 5639 | C6: 5789 | D6: 5916 | E6: 5851 | F6: 5817 | G6: 5739 | H6: 5686 | I6: 5668 | J6: 5638 | K6: 5791 | L6: 5950 | M6: 6031 | N6: =AVERAGE(B6:M6) -> 5792.9167
A7: Alaska | B7: 1059 | C7: 1058 | D7: 1134 | E7: 1345 | F7: 1322 | G7: 1253 | H7: 1345 | I7: 1322 | J7: 1253 | K7: 1214 | L7: 1201 | M7: 1157 | N7: =AVERAGE(B7:M7) -> 1221.9167
A8: Arizona | B8: 5136 | C8: 5096 | D8: 5169 | E8: 5118 | F8: 4997 | G8: 5023 | H8: 4930 | I8: 4882 | J8: 4744 | K8: 4627 | L8: 4561 | M8: 4430 | N8: =AVERAGE(B8:M8) -> 4892.75
A9: Arkansas | B9: 986 | C9: 969 | D9: 999 | E9: 919 | F9: 997 | G9: 954 | H9: 911 | I9: 879 | J9: 838 | K9: 788 | L9: 738 | M9: 719 | N9: =AVERAGE(B9:M9) -> 891.41667
A10: California | B10: 304580 | C10: 290338 | D10: 280009 | E10: 281659 | F10: 283148 | G10: 283229 | H10: 282901 | I10: 284394 | J10: 274381 | K10: 308527 | L10: 310010 | M10: 299797 | N10: =AVERAGE(B10:M10) -> 290247.75
A11: Colorado | B11: 12778 | C11: 12163 | D11: 12144 | E11: 12204 | F11: 12162 | G11: 12241 | H11: 12250 | I11: 12292 | J11: 12257 | K11: 12640 | L11: 12878 | M11: 13464 | N11: =AVERAGE(B11:M11) -> 12456.083
A12: Connecticut | B12: 5106 | C12: 5181 | D12: 5124 | E12: 5053 | F12: 5081 | G12: 5045 | H12: 5021 | I12: 5103 | J12: 5303 | K12: 5385 | L12: 5421 | M12: 5515 | N12: =AVERAGE(B12:M12) -> 5194.8333
A13: Delaware | B13: 2749 | C13: 2690 | D13: 2662 | E13: 2615 | F13: 2569 | G13: 2503 | H13: 2460 | I13: 2455 | J13: 2470 | K13: 2476 | L13: 2539 | M13: 2541 | N13: =AVERAGE(B13:M13) -> 2560.75
A14: District of Columbia | B14: 5374 | C14: 4885 | D14: 4908 | E14: 4737 | F14: 4576 | G14: 4766 | H14: 4694 | I14: 4835 | J14: 4884 | K14: 6004 | L14: 5738 | M14: 5274 | N14: =AVERAGE(B14:M14) -> 5056.25
A15: Florida | B15: 34929 | C15: 34015 | D15: 32986 | E15: 31649 | F15: 29599 | G15: 29402 | H15: 29046 | I15: 29042 | J15: 28754 | K15: 28070 | L15: 27281 | M15: 27469 | N15: =AVERAGE(B15:M15) -> 30186.833
A16: Georgia | B16: 4518 | C16: 4424 | D16: 4352 | E16: 4281 | F16: 4194 | G16: 4095 | H16: 4024 | I16: 4038 | J16: 4007 | K16: 3978 | L16: 3984 | M16: 3944 | N16: =AVERAGE(B16:M16) -> 4153.25
A17: Guam | B17: 149 | C17: 146 | D17: 157 | E17: 159 | F17: 172 | G17: 176 | H17: 194 | I17: 195 | J17: 204 | K17: 205 | L17: 198 | M17: 204 | N17: =AVERAGE(B17:M17) -> 179.91667
... A59: Wyoming | B59: 456 | C59: 466 | D59: 485 | E59: 483 | F59: 476 | G59: 467 | H59: 485 | I59: 482 | J59: 491 | K59: 486 | L59: 490 | M59: 476 | N59: =AVERAGE(B59:M59) -> 478.58333
A61: Notes:
A62: Fiscal year average is based on data Oct. 2023 through Sep. 2024

Sheet Two-par
A1: TANF: Total Number of Two Parent Families
A2: =TFam!$A$2 -> Fiscal Year 2024
A3: =TFam!$A$3 -> 45687
A4: State | B4: =TFam!B4 -> 45200 | C4: =TFam!C4 -> 45231 | D4: =TFam!D4 -> 45261 | E4: =TFam!E4 -> 45292 | F4: =TFam!F4 -> 45323 | G4: =TFam!G4 -> 45352 | H4: =TFam!H4 -> 45383 | I4: =TFam!I4 -> 45413 | ... N4: =TFam!N4 -> Average FY 2024
A5: U.S. Totals | B5: =SUM(B6:B59) -> 58246 | C5: =SUM(C6:C59) -> 53794 | D5: =SUM(D6:D59) -> 54504 | E5: =SUM(E6:E59) -> 54857 | F5: =SUM(F6:F59) -> 55322 | G5: =SUM(G6:G59) -> 55607 | H5: =SUM(H6:H59) -> 55811 | I5: =SUM(I6:I59) -> 56278 | ... M5: =SUM(M6:M59) -> 58459 | N5: =AVERAGE(B5:M5) -> 56430.917
A6: Alabama | B6: 38 | C6: 35 | D6: 34 | E6: 30 | F6: 29 | G6: 27 | H6: 29 | I6: 31 | J6: 34 | K6: 32 | L6: 35 | M6: 44 | N6: =AVERAGE(B6:M6) -> 33.166667
A7: Alaska | B7: 135 | C7: 133 | D7: 145 | E7: 179 | F7: 174 | G7: 155 | H7: 179 | I7: 174 | J7: 155 | K7: 154 | L7: 167 | M7: 156 | N7: =AVERAGE(B7:M7) -> 158.83333
A8: Arizona | B8: 253 | C8: 268 | D8: 296 | E8: 308 | F8: 327 | G8: 351 | H8: 343 | I8: 358 | J8: 359 | K8: 341 | L8: 318 | M8: 293 | N8: =AVERAGE(B8:M8) -> 317.91667
A9: Arkansas | B9: 39 | C9: 35 | D9: 37 | E9: 32 | F9: 41 | G9: 45 | H9: 42 | I9: 41 | J9: 32 | K9: 28 | L9: 26 | M9: 27 | N9: =AVERAGE(B9:M9) -> 35.416667
A10: California | B10: 36688 | C10: 32945 | D10: 34339 | E10: 34865 | F10: 35363 | G10: 35632 | H10: 35800 | I10: 36222 | J10: 35171 | K10: 39623 | L10: 39953 | M10: 38894 | N10: =AVERAGE(B10:M10) -> 36291.25
A11: Colorado | B11: 0 | C11: 0 | D11: 0 | E11: 0 | F11: 0 | G11: 0 | H11: 0 | I11: 0 | J11: 0 | K11: 0 | L11: 0 | M11: 0 | N11: =AVERAGE(B11:M11) -> 0
A12: Connecticut | B12: 0 | C12: 0 | D12: 0 | E12: 0 | F12: 0 | G12: 0 | H12: 0 | I12: 0 | J12: 0 | K12: 0 | L12: 0 | M12: 0 | N12: =AVERAGE(B12:M12) -> 0
A13: Delaware | B13: 7 | C13: 5 | D13: 6 | E13: 5 | F13: 2 | G13: 3 | H13: 3 | I13: 4 | J13: 5 | K13: 6 | L13: 6 | M13: 5 | N13: =AVERAGE(B13:M13) -> 4.75
A14: District of Columbia | B14: 0 | C14: 0 | D14: 0 | E14: 0 | F14: 0 | G14: 0 | H14: 0 | I14: 0 | J14: 0 | K14: 0 | L14: 0 | M14: 0 | N14: =AVERAGE(B14:M14) -> 0
A15: Florida | B15: 7645 | C15: 6993 | D15: 6224 | E15: 5554 | F15: 5032 | G15: 4868 | H15: 4699 | I15: 4537 | J15: 4331 | K15: 4126 | L15: 3739 | M15: 3520 | N15: =AVERAGE(B15:M15) -> 5105.6667
A16: Georgia | B16: 0 | C16: 0 | D16: 0 | E16: 0 | F16: 0 | G16: 0 | H16: 0 | I16: 0 | J16: 0 | K16: 2 | L16: 0 | M16: 0 | N16: =AVERAGE(B16:M16) -> 0.16666667
A17: Guam | B17: 5 | C17: 7 | D17: 7 | E17: 8 | F17: 9 | G17: 6 | H17: 7 | I17: 12 | J17: 12 | K17: 13 | L17: 12 | M17: 13 | N17: =AVERAGE(B17:M17) -> 9.25
... A59: Wyoming | B59: 13 | C59: 12 | D59: 11 | E59: 13 | F59: 17 | G59: 17 | H59: 20 | I59: 22 | J59: 23 | K59: 25 | L59: 25 | M59: 22 | N59: =AVERAGE(B59:M59) -> 18.333333
A61: Notes:
A62: =TFam!A62 -> Fiscal year average is based on data Oct. 2023 through Sep. 2024
A64: "-" - data inapplicable

Sheet One-par
A1: TANF: Total Number of One Parent Families
A2: =TFam!$A$2 -> Fiscal Year 2024
A3: =TFam!$A$3 -> 45687
A4: State | B4: =TFam!B4 -> 45200 | C4: =TFam!C4 -> 45231 | D4: =TFam!D4 -> 45261 | E4: =TFam!E4 -> 45292 | F4: =TFam!F4 -> 45323 | G4: =TFam!G4 -> 45352 | H4: =TFam!H4 -> 45383 | I4: =TFam!I4 -> 45413 | ... N4: =TFam!N4 -> Average FY 2024
A5: U.S. Totals | B5: =SUM(B6:B59) -> 442955 | C5: =SUM(C6:C59) -> 433579 | D5: =SUM(D6:D59) -> 425721 | E5: =SUM(E6:E59) -> 424576 | F5: =SUM(F6:F59) -> 427261 | G5: =SUM(G6:G59) -> 428338 | H5: =SUM(H6:H59) -> 429016 | I5: =SUM(I6:I59) -> 434037 | ... M5: =SUM(M6:M59) -> 462093 | N5: =AVERAGE(B5:M5) -> 438444.92
A6: Alabama | B6: 2227 | C6: 2358 | D6: 2521 | E6: 2476 | F6: 2468 | G6: 2393 | H6: 2354 | I6: 2353 | J6: 2373 | K6: 2471 | L6: 2612 | M6: 2722 | N6: =AVERAGE(B6:M6) -> 2444
A7: Alaska | B7: 565 | C7: 556 | D7: 611 | E7: 787 | F7: 766 | G7: 722 | H7: 787 | I7: 766 | J7: 722 | K7: 689 | L7: 670 | M7: 647 | N7: =AVERAGE(B7:M7) -> 690.66667
A8: Arizona | B8: 1346 | C8: 1317 | D8: 1328 | E8: 1301 | F8: 1272 | G8: 1297 | H8: 1295 | I8: 1284 | J8: 1251 | K8: 1218 | L8: 1191 | M8: 1170 | N8: =AVERAGE(B8:M8) -> 1272.5
A9: Arkansas | B9: 551 | C9: 537 | D9: 572 | E9: 515 | F9: 578 | G9: 538 | H9: 501 | I9: 488 | J9: 470 | K9: 432 | L9: 386 | M9: 391 | N9: =AVERAGE(B9:M9) -> 496.58333
A10: California | B10: 165800 | C10: 158689 | D10: 149817 | E10: 149645 | F10: 149891 | G10: 149141 | H10: 148668 | I10: 149622 | J10: 144691 | K10: 165248 | L10: 166663 | M10: 161793 | N10: =AVERAGE(B10:M10) -> 154972.33
A11: Colorado | B11: 8346 | C11: 7915 | D11: 7866 | E11: 7903 | F11: 7846 | G11: 7958 | H11: 8027 | I11: 8090 | J11: 8145 | K11: 8490 | L11: 8740 | M11: 9143 | N11: =AVERAGE(B11:M11) -> 8205.75
A12: Connecticut | B12: 1886 | C12: 1949 | D12: 1914 | E12: 1903 | F12: 1959 | G12: 1940 | H12: 1951 | I12: 2058 | J12: 2211 | K12: 2300 | L12: 2358 | M12: 2461 | N12: =AVERAGE(B12:M12) -> 2074.1667
A13: Delaware | B13: 812 | C13: 741 | D13: 724 | E13: 689 | F13: 673 | G13: 630 | H13: 593 | I13: 582 | J13: 573 | K13: 570 | L13: 606 | M13: 604 | N13: =AVERAGE(B13:M13) -> 649.75
A14: District of Columbia | B14: 3944 | C14: 3464 | D14: 3504 | E14: 3363 | F14: 3187 | G14: 3365 | H14: 3289 | I14: 3398 | J14: 3423 | K14: 4527 | L14: 4279 | M14: 3824 | N14: =AVERAGE(B14:M14) -> 3630.5833
A15: Florida | B15: 7966 | C15: 7802 | D15: 7514 | E15: 7085 | F15: 6567 | G15: 6841 | H15: 6966 | I15: 7131 | J15: 7397 | K15: 7345 | L15: 7203 | M15: 7598 | N15: =AVERAGE(B15:M15) -> 7284.5833
A16: Georgia | B16: 216 | C16: 194 | D16: 189 | E16: 180 | F16: 160 | G16: 147 | H16: 136 | I16: 143 | J16: 129 | K16: 101 | L16: 109 | M16: 105 | N16: =AVERAGE(B16:M16) -> 150.75
A17: Guam | B17: 43 | C17: 40 | D17: 42 | E17: 45 | F17: 49 | G17: 49 | H17: 53 | I17: 47 | J17: 51 | K17: 54 | L17: 51 | M17: 55 | N17: =AVERAGE(B17:M17) -> 48.25
... A59: Wyoming | B59: 225 | C59: 242 | D59: 261 | E59: 256 | F59: 249 | G59: 239 | H59: 251 | I59: 246 | J59: 252 | K59: 248 | L59: 255 | M59: 243 | N59: =AVERAGE(B59:M59) -> 247.25
A61: Notes:
A62: =TFam!A62 -> Fiscal year average is based on data Oct. 2023 through Sep. 2024

Sheet Zero-par
A1: TANF: Total Number of No Parent Families
A2: =TFam!$A$2 -> Fiscal Year 2024
A3: =TFam!$A$3 -> 45687
A4: State | B4: =TFam!B4 -> 45200 | C4: =TFam!C4 -> 45231 | D4: =TFam!D4 -> 45261 | E4: =TFam!E4 -> 45292 | F4: =TFam!F4 -> 45323 | G4: =TFam!G4 -> 45352 | H4: =TFam!H4 -> 45383 | I4: =TFam!I4 -> 45413 | ... N4: =TFam!N4 -> Average FY 2024
A5: U.S. Totals | B5: =SUM(B6:B59) -> 355329 | C5: =SUM(C6:C59) -> 350636 | D5: =SUM(D6:D59) -> 346775 | E5: =SUM(E6:E59) -> 347097 | F5: =SUM(F6:F59) -> 346509 | G5: =SUM(G6:G59) -> 345680 | H5: =SUM(H6:H59) -> 345211 | I5: =SUM(I6:I59) -> 345252 | ... M5: =SUM(M6:M59) -> 341012 | N5: =AVERAGE(B5:M5) -> 346332.83
A6: Alabama | B6: 3374 | C6: 3396 | D6: 3361 | E6: 3345 | F6: 3320 | G6: 3319 | H6: 3303 | I6: 3284 | J6: 3231 | K6: 3288 | L6: 3303 | M6: 3265 | N6: =AVERAGE(B6:M6) -> 3315.75
A7: Alaska | B7: 359 | C7: 369 | D7: 378 | E7: 379 | F7: 382 | G7: 376 | H7: 379 | I7: 382 | J7: 376 | K7: 371 | L7: 364 | M7: 354 | N7: =AVERAGE(B7:M7) -> 372.41667
A8: Arizona | B8: 3537 | C8: 3511 | D8: 3545 | E8: 3509 | F8: 3398 | G8: 3375 | H8: 3292 | I8: 3240 | J8: 3134 | K8: 3068 | L8: 3052 | M8: 2967 | N8: =AVERAGE(B8:M8) -> 3302.3333
A9: Arkansas | B9: 396 | C9: 397 | D9: 390 | E9: 372 | F9: 378 | G9: 371 | H9: 368 | I9: 350 | J9: 336 | K9: 328 | L9: 326 | M9: 301 | N9: =AVERAGE(B9:M9) -> 359.41667
A10: California | B10: 102092 | C10: 98704 | D10: 95853 | E10: 97149 | F10: 97894 | G10: 98456 | H10: 98433 | I10: 98550 | J10: 94519 | K10: 103656 | L10: 103394 | M10: 99110 | N10: =AVERAGE(B10:M10) -> 98984.167
A11: Colorado | B11: 4432 | C11: 4248 | D11: 4278 | E11: 4301 | F11: 4316 | G11: 4283 | H11: 4223 | I11: 4202 | J11: 4112 | K11: 4150 | L11: 4138 | M11: 4321 | N11: =AVERAGE(B11:M11) -> 4250.3333
A12: Connecticut | B12: 3220 | C12: 3232 | D12: 3210 | E12: 3150 | F12: 3122 | G12: 3105 | H12: 3070 | I12: 3045 | J12: 3092 | K12: 3085 | L12: 3063 | M12: 3054 | N12: =AVERAGE(B12:M12) -> 3120.6667
A13: Delaware | B13: 1930 | C13: 1944 | D13: 1932 | E13: 1921 | F13: 1894 | G13: 1870 | H13: 1864 | I13: 1869 | J13: 1892 | K13: 1900 | L13: 1927 | M13: 1932 | N13: =AVERAGE(B13:M13) -> 1906.25
A14: District of Columbia | B14: 1430 | C14: 1421 | D14: 1404 | E14: 1374 | F14: 1389 | G14: 1401 | H14: 1405 | I14: 1437 | J14: 1461 | K14: 1477 | L14: 1459 | M14: 1450 | N14: =AVERAGE(B14:M14) -> 1425.6667
A15: Florida | B15: 19318 | C15: 19220 | D15: 19248 | E15: 19010 | F15: 18000 | G15: 17693 | H15: 17381 | I15: 17374 | J15: 17026 | K15: 16599 | L15: 16339 | M15: 16351 | N15: =AVERAGE(B15:M15) -> 17796.583
A16: Georgia | B16: 4302 | C16: 4230 | D16: 4163 | E16: 4101 | F16: 4034 | G16: 3948 | H16: 3888 | I16: 3895 | J16: 3878 | K16: 3875 | L16: 3875 | M16: 3839 | N16: =AVERAGE(B16:M16) -> 4002.3333
A17: Guam | B17: 101 | C17: 99 | D17: 108 | E17: 106 | F17: 114 | G17: 121 | H17: 134 | I17: 136 | J17: 141 | K17: 138 | L17: 135 | M17: 136 | N17: =AVERAGE(B17:M17) -> 122.41667
... A59: Wyoming | B59: 218 | C59: 212 | D59: 213 | E59: 214 | F59: 210 | G59: 211 | H59: 214 | I59: 214 | J59: 216 | K59: 213 | L59: 210 | M59: 211 | N59: =AVERAGE(B59:M59) -> 213
A61: Notes:
A62: =TFam!A62 -> Fiscal year average is based on data Oct. 2023 through Sep. 2024

Sheet TRec
A1: TANF: Total Number of Recipients
A2: =TFam!$A$2 -> Fiscal Year 2024
A3: =TFam!$A$3 -> 45687
A4: State | B4: =TFam!B4 -> 45200 | C4: =TFam!C4 -> 45231 | D4: =TFam!D4 -> 45261 | E4: =TFam!E4 -> 45292 | F4: =TFam!F4 -> 45323 | G4: =TFam!G4 -> 45352 | H4: =TFam!H4 -> 45383 | I4: =TFam!I4 -> 45413 | ... N4: =TFam!N4 -> Average FY 2024
A5: U.S. Totals | B5: =SUM(B6:B59) -> 2100657 | C5: =SUM(C6:C59) -> 2048491 | D5: =SUM(D6:D59) -> 2022048 | E5: =SUM(E6:E59) -> 2023292 | F5: =SUM(F6:F59) -> 2028597 | G5: =SUM(G6:G59) -> 2028620 | H5: =SUM(H6:H59) -> 2027090 | I5: =SUM(I6:I59) -> 2050653 | ... M5: =SUM(M6:M59) -> 2118873 | N5: =AVERAGE(B5:M5) -> 2060968.2
A6: Alabama | B6: 13223 | C6: 13649 | D6: 14095 | E6: 13832 | F6: 13751 | G6: 13502 | H6: 13314 | I6: 13315 | J6: 13348 | K6: 13804 | L6: 14254 | M6: 14539 | N6: =AVERAGE(B6:M6) -> 13718.833
A7: Alaska | B7: 2930 | C7: 2940 | D7: 3122 | E7: 3719 | F7: 3662 | G7: 3440 | H7: 3719 | I7: 3662 | J7: 3440 | K7: 3340 | L7: 3338 | M7: 3204 | N7: =AVERAGE(B7:M7) -> 3376.3333
A8: Arizona | B8: 10589 | C8: 10474 | D8: 10658 | E8: 10618 | F8: 10420 | G8: 10525 | H8: 10310 | I8: 10244 | J8: 10076 | K8: 9806 | L8: 9652 | M8: 9307 | N8: =AVERAGE(B8:M8) -> 10223.25
A9: Arkansas | B9: 2466 | C9: 2403 | D9: 2481 | E9: 2246 | F9: 2513 | G9: 2366 | H9: 2265 | I9: 2182 | J9: 2046 | K9: 1902 | L9: 1759 | M9: 1748 | N9: =AVERAGE(B9:M9) -> 2198.0833
A10: California | B10: 812499 | C10: 770610 | D10: 744126 | E10: 748236 | F10: 752324 | G10: 751858 | H10: 749953 | I10: 754368 | J10: 725301 | K10: 815989 | L10: 819276 | M10: 790675 | N10: =AVERAGE(B10:M10) -> 769601.25
A11: Colorado | B11: 31358 | C11: 29839 | D11: 29775 | E11: 30006 | F11: 29815 | G11: 29949 | H11: 29950 | I11: 29996 | J11: 30000 | K11: 31070 | L11: 31795 | M11: 33199 | N11: =AVERAGE(B11:M11) -> 30562.667
A12: Connecticut | B12: 12101 | C12: 12283 | D12: 12167 | E12: 12028 | F12: 12149 | G12: 11981 | H12: 11956 | I12: 12196 | J12: 12660 | K12: 12881 | L12: 13048 | M12: 13303 | N12: =AVERAGE(B12:M12) -> 12396.083
A13: Delaware | B13: 7760 | C13: 7576 | D13: 7506 | E13: 7391 | F13: 7233 | G13: 7021 | H13: 6894 | I13: 6865 | J13: 6932 | K13: 6914 | L13: 7103 | M13: 7099 | N13: =AVERAGE(B13:M13) -> 7191.1667
A14: District of Columbia | B14: 17256 | C14: 15693 | D14: 15788 | E14: 15229 | F14: 14581 | G14: 15299 | H14: 15101 | I14: 15525 | J14: 15727 | K14: 19321 | L14: 18316 | M14: 16701 | N14: =AVERAGE(B14:M14) -> 16211.417
A15: Florida | B15: 71445 | C15: 68989 | D15: 65973 | E15: 62355 | F15: 57790 | G15: 57674 | H15: 57180 | I15: 57058 | J15: 56752 | K15: 55415 | L15: 53306 | M15: 53736 | N15: =AVERAGE(B15:M15) -> 59806.083
A16: Georgia | B16: 7914 | C16: 7777 | D16: 7601 | E16: 7453 | F16: 7277 | G16: 7128 | H16: 6952 | I16: 6972 | J16: 6894 | K16: 6861 | L16: 6891 | M16: 6830 | N16: =AVERAGE(B16:M16) -> 7212.5
A17: Guam | B17: 362 | C17: 372 | D17: 402 | E17: 401 | F17: 421 | G17: 413 | H17: 452 | I17: 455 | J17: 474 | K17: 480 | L17: 453 | M17: 473 | N17: =AVERAGE(B17:M17) -> 429.83333
... A59: Wyoming | B59: 1117 | C59: 1156 | D59: 1201 | E59: 1191 | F59: 1184 | G59: 1153 | H59: 1199 | I59: 1195 | J59: 1210 | K59: 1197 | L59: 1216 | M59: 1174 | N59: =AVERAGE(B59:M59) -> 1182.75
A61: Notes:
A62: =TFam!A62 -> Fiscal year average is based on data Oct. 2023 through Sep. 2024

Sheet Adults
A1: TANF: Total Number of Adult Recipients
A2: =TFam!$A$2 -> Fiscal Year 2024
A3: =TFam!$A$3 -> 45687
A4: State | B4: =TFam!B4 -> 45200 | C4: =TFam!C4 -> 45231 | D4: =TFam!D4 -> 45261 | E4: =TFam!E4 -> 45292 | F4: =TFam!F4 -> 45323 | G4: =TFam!G4 -> 45352 | H4: =TFam!H4 -> 45383 | I4: =TFam!I4 -> 45413 | ... N4: =TFam!N4 -> Average FY 2024
A5: U.S. Totals | B5: =SUM(B6:B59) -> 566121 | C5: =SUM(C6:C59) -> 549891 | D5: =SUM(D6:D59) -> 544359 | E5: =SUM(E6:E59) -> 545359 | F5: =SUM(F6:F59) -> 547656 | G5: =SUM(G6:G59) -> 549318 | H5: =SUM(H6:H59) -> 550073 | I5: =SUM(I6:I59) -> 559353 | ... M5: =SUM(M6:M59) -> 585207 | N5: =AVERAGE(B5:M5) -> 560124.5
A6: Alabama | B6: 2360 | C6: 2483 | D6: 2644 | E6: 2592 | F6: 2582 | G6: 2505 | H6: 2464 | I6: 2474 | J6: 2507 | K6: 2639 | L6: 2767 | M6: 2870 | N6: =AVERAGE(B6:M6) -> 2573.9167
A7: Alaska | B7: 872 | C7: 862 | D7: 937 | E7: 1190 | F7: 1157 | G7: 1074 | H7: 1190 | I7: 1157 | J7: 1074 | K7: 1036 | L7: 1042 | M7: 996 | N7: =AVERAGE(B7:M7) -> 1048.9167
A8: Arizona | B8: 1870 | C8: 1867 | D8: 1942 | E8: 1937 | F8: 1951 | G8: 2022 | H8: 2000 | I8: 2023 | J8: 1996 | K8: 1928 | L8: 1853 | M8: 1785 | N8: =AVERAGE(B8:M8) -> 1931.1667
A9: Arkansas | B9: 629 | C9: 608 | D9: 647 | E9: 579 | F9: 660 | G9: 628 | H9: 585 | I9: 570 | J9: 534 | K9: 488 | L9: 438 | M9: 445 | N9: =AVERAGE(B9:M9) -> 567.58333
A10: California | B10: 219933 | C10: 206846 | D10: 200984 | E10: 201974 | F10: 203136 | G10: 203156 | H10: 202846 | I10: 204462 | J10: 197720 | K10: 222030 | L10: 223759 | M10: 217063 | N10: =AVERAGE(B10:M10) -> 208659.08
A11: Colorado | B11: 8584 | C11: 8158 | D11: 8138 | E11: 8206 | F11: 8170 | G11: 8281 | H11: 8308 | I11: 8365 | J11: 8441 | K11: 8781 | L11: 8999 | M11: 9406 | N11: =AVERAGE(B11:M11) -> 8486.4167
A12: Connecticut | B12: 3411 | C12: 3484 | D12: 3444 | E12: 3418 | F12: 3486 | G12: 3439 | H12: 3435 | I12: 3532 | J12: 3706 | K12: 3803 | L12: 3876 | M12: 4001 | N12: =AVERAGE(B12:M12) -> 3586.25
A13: Delaware | B13: 3119 | C13: 3055 | D13: 3023 | E13: 2970 | F13: 2913 | G13: 2843 | H13: 2808 | I13: 2804 | J13: 2830 | K13: 2837 | L13: 2902 | M13: 2906 | N13: =AVERAGE(B13:M13) -> 2917.5
A14: District of Columbia | B14: 3944 | C14: 3464 | D14: 3504 | E14: 3363 | F14: 3187 | G14: 3365 | H14: 3289 | I14: 3398 | J14: 3423 | K14: 4527 | L14: 4279 | M14: 3824 | N14: =AVERAGE(B14:M14) -> 3630.5833
A15: Florida | B15: 26025 | C15: 24677 | D15: 22754 | E15: 21014 | F15: 19185 | G15: 19166 | H15: 19060 | I15: 18977 | J15: 18893 | K15: 18447 | L15: 17457 | M15: 17442 | N15: =AVERAGE(B15:M15) -> 20258.083
A16: Georgia | B16: 217 | C16: 197 | D16: 192 | E16: 181 | F16: 159 | G16: 148 | H16: 133 | I16: 140 | J16: 126 | K16: 149 | L16: 155 | M16: 159 | N16: =AVERAGE(B16:M16) -> 163
A17: Guam | B17: 54 | C17: 55 | D17: 58 | E17: 60 | F17: 67 | G17: 63 | H17: 69 | I17: 72 | J17: 76 | K17: 82 | L17: 76 | M17: 83 | N17: =AVERAGE(B17:M17) -> 67.916667
... A59: Wyoming | B59: 251 | C59: 266 | D59: 283 | E59: 282 | F59: 282 | G59: 272 | H59: 292 | I59: 291 | J59: 298 | K59: 297 | L59: 305 | M59: 287 | N59: =AVERAGE(B59:M59) -> 283.83333
A61: Notes:
A62: =TFam!A62 -> Fiscal year average is based on data Oct. 2023 through Sep. 2024

Sheet Children
A1: TANF: Total Number of Child Recipients
A2: =TFam!$A$2 -> Fiscal Year 2024
A3: =TFam!$A$3 -> 45687
A4: State | B4: =TFam!B4 -> 45200 | C4: =TFam!C4 -> 45231 | D4: =TFam!D4 -> 45261 | E4: =TFam!E4 -> 45292 | F4: =TFam!F4 -> 45323 | G4: =TFam!G4 -> 45352 | H4: =TFam!H4 -> 45383 | I4: =TFam!I4 -> 45413 | ... N4: =TFam!N4 -> Average FY 2024
A5: U.S. Totals | B5: =SUM(B6:B59) -> 1534536 | C5: =SUM(C6:C59) -> 1498600 | D5: =SUM(D6:D59) -> 1477689 | E5: =SUM(E6:E59) -> 1477933 | F5: =SUM(F6:F59) -> 1480941 | G5: =SUM(G6:G59) -> 1479302 | H5: =SUM(H6:H59) -> 1477017 | I5: =SUM(I6:I59) -> 1491300 | ... M5: =SUM(M6:M59) -> 1533666 | N5: =AVERAGE(B5:M5) -> 1500843.8
A6: Alabama | B6: 10863 | C6: 11166 | D6: 11451 | E6: 11240 | F6: 11169 | G6: 10997 | H6: 10850 | I6: 10841 | J6: 10841 | K6: 11165 | L6: 11487 | M6: 11669 | N6: =AVERAGE(B6:M6) -> 11144.917
A7: Alaska | B7: 2058 | C7: 2078 | D7: 2185 | E7: 2529 | F7: 2505 | G7: 2366 | H7: 2529 | I7: 2505 | J7: 2366 | K7: 2304 | L7: 2296 | M7: 2208 | N7: =AVERAGE(B7:M7) -> 2327.4167
A8: Arizona | B8: 8719 | C8: 8607 | D8: 8716 | E8: 8681 | F8: 8469 | G8: 8503 | H8: 8310 | I8: 8221 | J8: 8080 | K8: 7878 | L8: 7799 | M8: 7522 | N8: =AVERAGE(B8:M8) -> 8292.0833
A9: Arkansas | B9: 1837 | C9: 1795 | D9: 1834 | E9: 1667 | F9: 1853 | G9: 1738 | H9: 1680 | I9: 1612 | J9: 1512 | K9: 1414 | L9: 1321 | M9: 1303 | N9: =AVERAGE(B9:M9) -> 1630.5
A10: California | B10: 592566 | C10: 563764 | D10: 543142 | E10: 546262 | F10: 549188 | G10: 548702 | H10: 547107 | I10: 549906 | J10: 527581 | K10: 593959 | L10: 595517 | M10: 573612 | N10: =AVERAGE(B10:M10) -> 560942.17
A11: Colorado | B11: 22774 | C11: 21681 | D11: 21637 | E11: 21800 | F11: 21645 | G11: 21668 | H11: 21642 | I11: 21631 | J11: 21559 | K11: 22289 | L11: 22796 | M11: 23793 | N11: =AVERAGE(B11:M11) -> 22076.25
A12: Connecticut | B12: 8690 | C12: 8799 | D12: 8723 | E12: 8610 | F12: 8663 | G12: 8542 | H12: 8521 | I12: 8664 | J12: 8954 | K12: 9078 | L12: 9172 | M12: 9302 | N12: =AVERAGE(B12:M12) -> 8809.8333
A13: Delaware | B13: 4641 | C13: 4521 | D13: 4483 | E13: 4421 | F13: 4320 | G13: 4178 | H13: 4086 | I13: 4061 | J13: 4102 | K13: 4077 | L13: 4201 | M13: 4193 | N13: =AVERAGE(B13:M13) -> 4273.6667
A14: District of Columbia | B14: 13312 | C14: 12229 | D14: 12284 | E14: 11866 | F14: 11394 | G14: 11934 | H14: 11812 | I14: 12127 | J14: 12304 | K14: 14794 | L14: 14037 | M14: 12877 | N14: =AVERAGE(B14:M14) -> 12580.833
A15: Florida | B15: 45420 | C15: 44312 | D15: 43219 | E15: 41341 | F15: 38605 | G15: 38508 | H15: 38120 | I15: 38081 | J15: 37859 | K15: 36968 | L15: 35849 | M15: 36294 | N15: =AVERAGE(B15:M15) -> 39548
A16: Georgia | B16: 7697 | C16: 7580 | D16: 7409 | E16: 7272 | F16: 7118 | G16: 6980 | H16: 6819 | I16: 6832 | J16: 6768 | K16: 6712 | L16: 6736 | M16: 6671 | N16: =AVERAGE(B16:M16) -> 7049.5
A17: Guam | B17: 308 | C17: 317 | D17: 344 | E17: 341 | F17: 354 | G17: 350 | H17: 383 | I17: 383 | J17: 398 | K17: 398 | L17: 377 | M17: 390 | N17: =AVERAGE(B17:M17) -> 361.91667
... A59: Wyoming | B59: 866 | C59: 890 | D59: 918 | E59: 909 | F59: 902 | G59: 881 | H59: 907 | I59: 904 | J59: 912 | K59: 900 | L59: 911 | M59: 887 | N59: =AVERAGE(B59:M59) -> 898.91667
A61: Notes:
A62: =TFam!A62 -> Fiscal year average is based on data Oct. 2023 through Sep. 2024

Sheet Oct23
A1: October 2023
A2: Temporary Assistance for Needy Families (TANF)
A3: State | B3: Total Families | C3: Two Parent Families | D3: One Parent Families | E3: No Parent Families | F3: Total Recipients | G3: Adults | H3: Children
A4: U.S. Totals | B4: =TFam!B5 -> 856530 | C4: ='Two-par'!B5 -> 58246 | D4: ='One-par'!B5 -> 442955 | E4: ='Zero-par'!B5 -> 355329 | F4: =TRec!B5 -> 2100657 | G4: =Adults!B5 -> 566121 | H4: =Children!B5 -> 1534536
A5: Alabama | B5: =TFam!B6 -> 5639 | C5: ='Two-par'!B6 -> 38 | D5: ='One-par'!B6 -> 2227 | E5: ='Zero-par'!B6 -> 3374 | F5: =TRec!B6 -> 13223 | G5: =Adults!B6 -> 2360 | H5: =Children!B6 -> 10863
A6: Alaska | B6: =TFam!B7 -> 1059 | C6: ='Two-par'!B7 -> 135 | D6: ='One-par'!B7 -> 565 | E6: ='Zero-par'!B7 -> 359 | F6: =TRec!B7 -> 2930 | G6: =Adults!B7 -> 872 | H6: =Children!B7 -> 2058
A7: Arizona | B7: =TFam!B8 -> 5136 | C7: ='Two-par'!B8 -> 253 | D7: ='One-par'!B8 -> 1346 | E7: ='Zero-par'!B8 -> 3537 | F7: =TRec!B8 -> 10589 | G7: =Adults!B8 -> 1870 | H7: =Children!B8 -> 8719
A8: Arkansas | B8: =TFam!B9 -> 986 | C8: ='Two-par'!B9 -> 39 | D8: ='One-par'!B9 -> 551 | E8: ='Zero-par'!B9 -> 396 | F8: =TRec!B9 -> 2466 | G8: =Adults!B9 -> 629 | H8: =Children!B9 -> 1837
A9: California | B9: =TFam!B10 -> 304580 | C9: ='Two-par'!B10 -> 36688 | D9: ='One-par'!B10 -> 165800 | E9: ='Zero-par'!B10 -> 102092 | F9: =TRec!B10 -> 812499 | G9: =Adults!B10 -> 219933 | H9: =Children!B10 -> 592566
A10: Colorado | B10: =TFam!B11 -> 12778 | C10: ='Two-par'!B11 -> 0 | D10: ='One-par'!B11 -> 8346 | E10: ='Zero-par'!B11 -> 4432 | F10: =TRec!B11 -> 31358 | G10: =Adults!B11 -> 8584 | H10: =Children!B11 -> 22774
A11: Connecticut | B11: =TFam!B12 -> 5106 | C11: ='Two-par'!B12 -> 0 | D11: ='One-par'!B12 -> 1886 | E11: ='Zero-par'!B12 -> 3220 | F11: =TRec!B12 -> 12101 | G11: =Adults!B12 -> 3411 | H11: =Children!B12 -> 8690
A12: Delaware | B12: =TFam!B13 -> 2749 | C12: ='Two-par'!B13 -> 7 | D12: ='One-par'!B13 -> 812 | E12: ='Zero-par'!B13 -> 1930 | F12: =TRec!B13 -> 7760 | G12: =Adults!B13 -> 3119 | H12: =Children!B13 -> 4641
A13: District of Columbia | B13: =TFam!B14 -> 5374 | C13: ='Two-par'!B14 -> 0 | D13: ='One-par'!B14 -> 3944 | E13: ='Zero-par'!B14 -> 1430 | F13: =TRec!B14 -> 17256 | G13: =Adults!B14 -> 3944 | H13: =Children!B14 -> 13312
A14: Florida | B14: =TFam!B15 -> 34929 | C14: ='Two-par'!B15 -> 7645 | D14: ='One-par'!B15 -> 7966 | E14: ='Zero-par'!B15 -> 19318 | F14: =TRec!B15 -> 71445 | G14: =Adults!B15 -> 26025 | H14: =Children!B15 -> 45420
A15: Georgia | B15: =TFam!B16 -> 4518 | C15: ='Two-par'!B16 -> 0 | D15: ='One-par'!B16 -> 216 | E15: ='Zero-par'!B16 -> 4302 | F15: =TRec!B16 -> 7914 | G15: =Adults!B16 -> 217 | H15: =Children!B16 -> 7697
... A58: Wyoming | B58: =TFam!B59 -> 456 | C58: ='Two-par'!B59 -> 13 | D58: ='One-par'!B59 -> 225 | E58: ='Zero-par'!B59 -> 218 | F58: =TRec!B59 -> 1117 | G58: =Adults!B59 -> 251 | H58: =Children!B59 -> 866
A59: =TFam!$A$3 -> 45687
A61: Notes:
A62: "-" - data inapplicable

Sheet Nov23
A1: November 2023
A2: ='Oct23'!$A$2 -> Temporary Assistance for Needy Families (TANF)
A3: State | B3: Total Families | C3: Two Parent Families | D3: One Parent Families | E3: No Parent Families | F3: Total Recipients | G3: Adults | H3: Children
A4: U.S. Totals | B4: =TFam!C5 -> 838009 | C4: ='Two-par'!C5 -> 53794 | D4: ='One-par'!C5 -> 433579 | E4: ='Zero-par'!C5 -> 350636 | F4: =TRec!C5 -> 2048491 | G4: =Adults!C5 -> 549891 | H4: =Children!C5 -> 1498600
A5: Alabama | B5: =TFam!C6 -> 5789 | C5: ='Two-par'!C6 -> 35 | D5: ='One-par'!C6 -> 2358 | E5: ='Zero-par'!C6 -> 3396 | F5: =TRec!C6 -> 13649 | G5: =Adults!C6 -> 2483 | H5: =Children!C6 -> 11166
A6: Alaska | B6: =TFam!C7 -> 1058 | C6: ='Two-par'!C7 -> 133 | D6: ='One-par'!C7 -> 556 | E6: ='Zero-par'!C7 -> 369 | F6: =TRec!C7 -> 2940 | G6: =Adults!C7 -> 862 | H6: =Children!C7 -> 2078
A7: Arizona | B7: =TFam!C8 -> 5096 | C7: ='Two-par'!C8 -> 268 | D7: ='One-par'!C8 -> 1317 | E7: ='Zero-par'!C8 -> 3511 | F7: =TRec!C8 -> 10474 | G7: =Adults!C8 -> 1867 | H7: =Children!C8 -> 8607
A8: Arkansas | B8: =TFam!C9 -> 969 | C8: ='Two-par'!C9 -> 35 | D8: ='One-par'!C9 -> 537 | E8: ='Zero-par'!C9 -> 397 | F8: =TRec!C9 -> 2403 | G8: =Adults!C9 -> 608 | H8: =Children!C9 -> 1795
A9: California | B9: =TFam!C10 -> 290338 | C9: ='Two-par'!C10 -> 32945 | D9: ='One-par'!C10 -> 158689 | E9: ='Zero-par'!C10 -> 98704 | F9: =TRec!C10 -> 770610 | G9: =Adults!C10 -> 206846 | H9: =Children!C10 -> 563764
A10: Colorado | B10: =TFam!C11 -> 12163 | C10: ='Two-par'!C11 -> 0 | D10: ='One-par'!C11 -> 7915 | E10: ='Zero-par'!C11 -> 4248 | F10: =TRec!C11 -> 29839 | G10: =Adults!C11 -> 8158 | H10: =Children!C11 -> 21681
A11: Connecticut | B11: =TFam!C12 -> 5181 | C11: ='Two-par'!C12 -> 0 | D11: ='One-par'!C12 -> 1949 | E11: ='Zero-par'!C12 -> 3232 | F11: =TRec!C12 -> 12283 | G11: =Adults!C12 -> 3484 | H11: =Children!C12 -> 8799
A12: Delaware | B12: =TFam!C13 -> 2690 | C12: ='Two-par'!C13 -> 5 | D12: ='One-par'!C13 -> 741 | E12: ='Zero-par'!C13 -> 1944 | F12: =TRec!C13 -> 7576 | G12: =Adults!C13 -> 3055 | H12: =Children!C13 -> 4521
A13: District of Columbia | B13: =TFam!C14 -> 4885 | C13: ='Two-par'!C14 -> 0 | D13: ='One-par'!C14 -> 3464 | E13: ='Zero-par'!C14 -> 1421 | F13: =TRec!C14 -> 15693 | G13: =Adults!C14 -> 3464 | H13: =Children!C14 -> 12229
A14: Florida | B14: =TFam!C15 -> 34015 | C14: ='Two-par'!C15 -> 6993 | D14: ='One-par'!C15 -> 7802 | E14: ='Zero-par'!C15 -> 19220 | F14: =TRec!C15 -> 68989 | G14: =Adults!C15 -> 24677 | H14: =Children!C15 -> 44312
A15: Georgia | B15: =TFam!C16 -> 4424 | C15: ='Two-par'!C16 -> 0 | D15: ='One-par'!C16 -> 194 | E15: ='Zero-par'!C16 -> 4230 | F15: =TRec!C16 -> 7777 | G15: =Adults!C16 -> 197 | H15: =Children!C16 -> 7580
... A58: Wyoming | B58: =TFam!C59 -> 466 | C58: ='Two-par'!C59 -> 12 | D58: ='One-par'!C59 -> 242 | E58: ='Zero-par'!C59 -> 212 | F58: =TRec!C59 -> 1156 | G58: =Adults!C59 -> 266 | H58: =Children!C59 -> 890
A59: =TFam!$A$3 -> 45687
A60: ='Oct23'!A60
A61: ='Oct23'!A61 -> Notes:
A62: ='Oct23'!A62 -> "-" - data inapplicable

Sheet Dec23
A1: December 2023
A2: ='Oct23'!$A$2 -> Temporary Assistance for Needy Families (TANF)
A3: State | B3: Total Families | C3: Two Parent Families | D3: One Parent Families | E3: No Parent Families | F3: Total Recipients | G3: Adults | H3: Children
A4: U.S. Totals | B4: =TFam!D5 -> 827000 | C4: ='Two-par'!D5 -> 54504 | D4: ='One-par'!D5 -> 425721 | E4: ='Zero-par'!D5 -> 346775 | F4: =TRec!D5 -> 2022048 | G4: =Adults!D5 -> 544359 | H4: =Children!D5 -> 1477689
A5: Alabama | B5: =TFam!D6 -> 5916 | C5: ='Two-par'!D6 -> 34 | D5: ='One-par'!D6 -> 2521 | E5: ='Zero-par'!D6 -> 3361 | F5: =TRec!D6 -> 14095 | G5: =Adults!D6 -> 2644 | H5: =Children!D6 -> 11451
A6: Alaska | B6: =TFam!D7 -> 1134 | C6: ='Two-par'!D7 -> 145 | D6: ='One-par'!D7 -> 611 | E6: ='Zero-par'!D7 -> 378 | F6: =TRec!D7 -> 3122 | G6: =Adults!D7 -> 937 | H6: =Children!D7 -> 2185
A7: Arizona | B7: =TFam!D8 -> 5169 | C7: ='Two-par'!D8 -> 296 | D7: ='One-par'!D8 -> 1328 | E7: ='Zero-par'!D8 -> 3545 | F7: =TRec!D8 -> 10658 | G7: =Adults!D8 -> 1942 | H7: =Children!D8 -> 8716
A8: Arkansas | B8: =TFam!D9 -> 999 | C8: ='Two-par'!D9 -> 37 | D8: ='One-par'!D9 -> 572 | E8: ='Zero-par'!D9 -> 390 | F8: =TRec!D9 -> 2481 | G8: =Adults!D9 -> 647 | H8: =Children!D9 -> 1834
A9: California | B9: =TFam!D10 -> 280009 | C9: ='Two-par'!D10 -> 34339 | D9: ='One-par'!D10 -> 149817 | E9: ='Zero-par'!D10 -> 95853 | F9: =TRec!D10 -> 744126 | G9: =Adults!D10 -> 200984 | H9: =Children!D10 -> 543142
A10: Colorado | B10: =TFam!D11 -> 12144 | C10: ='Two-par'!D11 -> 0 | D10: ='One-par'!D11 -> 7866 | E10: ='Zero-par'!D11 -> 4278 | F10: =TRec!D11 -> 29775 | G10: =Adults!D11 -> 8138 | H10: =Children!D11 -> 21637
A11: Connecticut | B11: =TFam!D12 -> 5124 | C11: ='Two-par'!D12 -> 0 | D11: ='One-par'!D12 -> 1914 | E11: ='Zero-par'!D12 -> 3210 | F11: =TRec!D12 -> 12167 | G11: =Adults!D12 -> 3444 | H11: =Children!D12 -> 8723
A12: Delaware | B12: =TFam!D13 -> 2662 | C12: ='Two-par'!D13 -> 6 | D12: ='One-par'!D13 -> 724 | E12: ='Zero-par'!D13 -> 1932 | F12: =TRec!D13 -> 7506 | G12: =Adults!D13 -> 3023 | H12: =Children!D13 -> 4483
A13: District of Columbia | B13: =TFam!D14 -> 4908 | C13: ='Two-par'!D14 -> 0 | D13: ='One-par'!D14 -> 3504 | E13: ='Zero-par'!D14 -> 1404 | F13: =TRec!D14 -> 15788 | G13: =Adults!D14 -> 3504 | H13: =Children!D14 -> 12284
A14: Florida | B14: =TFam!D15 -> 32986 | C14: ='Two-par'!D15 -> 6224 | D14: ='One-par'!D15 -> 7514 | E14: ='Zero-par'!D15 -> 19248 | F14: =TRec!D15 -> 65973 | G14: =Adults!D15 -> 22754 | H14: =Children!D15 -> 43219
A15: Georgia | B15: =TFam!D16 -> 4352 | C15: ='Two-par'!D16 -> 0 | D15: ='One-par'!D16 -> 189 | E15: ='Zero-par'!D16 -> 4163 | F15: =TRec!D16 -> 7601 | G15: =Adults!D16 -> 192 | H15: =Children!D16 -> 7409
... A58: Wyoming | B58: =TFam!D59 -> 485 | C58: ='Two-par'!D59 -> 11 | D58: ='One-par'!D59 -> 261 | E58: ='Zero-par'!D59 -> 213 | F58: =TRec!D59 -> 1201 | G58: =Adults!D59 -> 283 | H58: =Children!D59 -> 918
A59: =TFam!$A$3 -> 45687
A60: ='Oct23'!A60
A61: ='Oct23'!A61 -> Notes:
A62: ='Oct23'!A62 -> "-" - data inapplicable

Sheet Jan24
A1: January 2024
A2: ='Oct23'!$A$2 -> Temporary Assistance for Needy Families (TANF)
A3: State | B3: Total Families | C3: Two Parent Families | D3: One Parent Families | E3: No Parent Families | F3: Total Recipients | G3: Adults | H3: Children
A4: U.S. Totals | B4: =TFam!E5 -> 826530 | C4: ='Two-par'!E5 -> 54857 | D4: ='One-par'!E5 -> 424576 | E4: ='Zero-par'!E5 -> 347097 | F4: =TRec!E5 -> 2023292 | G4: =Adults!E5 -> 545359 | H4: =Children!E5 -> 1477933
A5: Alabama | B5: =TFam!E6 -> 5851 | C5: ='Two-par'!E6 -> 30 | D5: ='One-par'!E6 -> 2476 | E5: ='Zero-par'!E6 -> 3345 | F5: =TRec!E6 -> 13832 | G5: =Adults!E6 -> 2592 | H5: =Children!E6 -> 11240
A6: Alaska | B6: =TFam!E7 -> 1345 | C6: ='Two-par'!E7 -> 179 | D6: ='One-par'!E7 -> 787 | E6: ='Zero-par'!E7 -> 379 | F6: =TRec!E7 -> 3719 | G6: =Adults!E7 -> 1190 | H6: =Children!E7 -> 2529
A7: Arizona | B7: =TFam!E8 -> 5118 | C7: ='Two-par'!E8 -> 308 | D7: ='One-par'!E8 -> 1301 | E7: ='Zero-par'!E8 -> 3509 | F7: =TRec!E8 -> 10618 | G7: =Adults!E8 -> 1937 | H7: =Children!E8 -> 8681
A8: Arkansas | B8: =TFam!E9 -> 919 | C8: ='Two-par'!E9 -> 32 | D8: ='One-par'!E9 -> 515 | E8: ='Zero-par'!E9 -> 372 | F8: =TRec!E9 -> 2246 | G8: =Adults!E9 -> 579 | H8: =Children!E9 -> 1667
A9: California | B9: =TFam!E10 -> 281659 | C9: ='Two-par'!E10 -> 34865 | D9: ='One-par'!E10 -> 149645 | E9: ='Zero-par'!E10 -> 97149 | F9: =TRec!E10 -> 748236 | G9: =Adults!E10 -> 201974 | H9: =Children!E10 -> 546262
A10: Colorado | B10: =TFam!E11 -> 12204 | C10: ='Two-par'!E11 -> 0 | D10: ='One-par'!E11 -> 7903 | E10: ='Zero-par'!E11 -> 4301 | F10: =TRec!E11 -> 30006 | G10: =Adults!E11 -> 8206 | H10: =Children!E11 -> 21800
A11: Connecticut | B11: =TFam!E12 -> 5053 | C11: ='Two-par'!E12 -> 0 | D11: ='One-par'!E12 -> 1903 | E11: ='Zero-par'!E12 -> 3150 | F11: =TRec!E12 -> 12028 | G11: =Adults!E12 -> 3418 | H11: =Children!E12 -> 8610
A12: Delaware | B12: =TFam!E13 -> 2615 | C12: ='Two-par'!E13 -> 5 | D12: ='One-par'!E13 -> 689 | E12: ='Zero-par'!E13 -> 1921 | F12: =TRec!E13 -> 7391 | G12: =Adults!E13 -> 2970 | H12: =Children!E13 -> 4421
A13: District of Columbia | B13: =TFam!E14 -> 4737 | C13: ='Two-par'!E14 -> 0 | D13: ='One-par'!E14 -> 3363 | E13: ='Zero-par'!E14 -> 1374 | F13: =TRec!E14 -> 15229 | G13: =Adults!E14 -> 3363 | H13: =Children!E14 -> 11866
A14: Florida | B14: =TFam!E15 -> 31649 | C14: ='Two-par'!E15 -> 5554 | D14: ='One-par'!E15 -> 7085 | E14: ='Zero-par'!E15 -> 19010 | F14: =TRec!E15 -> 62355 | G14: =Adults!E15 -> 21014 | H14: =Children!E15 -> 41341
A15: Georgia | B15: =TFam!E16 -> 4281 | C15: ='Two-par'!E16 -> 0 | D15: ='One-par'!E16 -> 180 | E15: ='Zero-par'!E16 -> 4101 | F15: =TRec!E16 -> 7453 | G15: =Adults!E16 -> 181 | H15: =Children!E16 -> 7272
... A58: Wyoming | B58: =TFam!E59 -> 483 | C58: ='Two-par'!E59 -> 13 | D58: ='One-par'!E59 -> 256 | E58: ='Zero-par'!E59 -> 214 | F58: =TRec!E59 -> 1191 | G58: =Adults!E59 -> 282 | H58: =Children!E59 -> 909
A59: =TFam!$A$3 -> 45687
A60: ='Oct23'!A60
A61: ='Oct23'!A61 -> Notes:
A62: ='Oct23'!A62 -> "-" - data inapplicable

Sheet Feb24
A1: February 2024
A2: ='Oct23'!$A$2 -> Temporary Assistance for Needy Families (TANF)
A3: State | B3: Total Families | C3: Two Parent Families | D3: One Parent Families | E3: No Parent Families | F3: Total Recipients | G3: Adults | H3: Children
A4: U.S. Totals | B4: =TFam!F5 -> 829092 | C4: ='Two-par'!F5 -> 55322 | D4: ='One-par'!F5 -> 427261 | E4: ='Zero-par'!F5 -> 346509 | F4: =TRec!F5 -> 2028597 | G4: =Adults!F5 -> 547656 | H4: =Children!F5 -> 1480941
A5: Alabama | B5: =TFam!F6 -> 5817 | C5: ='Two-par'!F6 -> 29 | D5: ='One-par'!F6 -> 2468 | E5: ='Zero-par'!F6 -> 3320 | F5: =TRec!F6 -> 13751 | G5: =Adults!F6 -> 2582 | H5: =Children!F6 -> 11169
A6: Alaska | B6: =TFam!F7 -> 1322 | C6: ='Two-par'!F7 -> 174 | D6: ='One-par'!F7 -> 766 | E6: ='Zero-par'!F7 -> 382 | F6: =TRec!F7 -> 3662 | G6: =Adults!F7 -> 1157 | H6: =Children!F7 -> 2505
A7: Arizona | B7: =TFam!F8 -> 4997 | C7: ='Two-par'!F8 -> 327 | D7: ='One-par'!F8 -> 1272 | E7: ='Zero-par'!F8 -> 3398 | F7: =TRec!F8 -> 10420 | G7: =Adults!F8 -> 1951 | H7: =Children!F8 -> 8469
A8: Arkansas | B8: =TFam!F9 -> 997 | C8: ='Two-par'!F9 -> 41 | D8: ='One-par'!F9 -> 578 | E8: ='Zero-par'!F9 -> 378 | F8: =TRec!F9 -> 2513 | G8: =Adults!F9 -> 660 | H8: =Children!F9 -> 1853
A9: California | B9: =TFam!F10 -> 283148 | C9: ='Two-par'!F10 -> 35363 | D9: ='One-par'!F10 -> 149891 | E9: ='Zero-par'!F10 -> 97894 | F9: =TRec!F10 -> 752324 | G9: =Adults!F10 -> 203136 | H9: =Children!F10 -> 549188
A10: Colorado | B10: =TFam!F11 -> 12162 | C10: ='Two-par'!F11 -> 0 | D10: ='One-par'!F11 -> 7846 | E10: ='Zero-par'!F11 -> 4316 | F10: =TRec!F11 -> 29815 | G10: =Adults!F11 -> 8170 | H10: =Children!F11 -> 21645
A11: Connecticut | B11: =TFam!F12 -> 5081 | C11: ='Two-par'!F12 -> 0 | D11: ='One-par'!F12 -> 1959 | E11: ='Zero-par'!F12 -> 3122 | F11: =TRec!F12 -> 12149 | G11: =Adults!F12 -> 3486 | H11: =Children!F12 -> 8663
A12: Delaware | B12: =TFam!F13 -> 2569 | C12: ='Two-par'!F13 -> 2 | D12: ='One-par'!F13 -> 673 | E12: ='Zero-par'!F13 -> 1894 | F12: =TRec!F13 -> 7233 | G12: =Adults!F13 -> 2913 | H12: =Children!F13 -> 4320
A13: District of Columbia | B13: =TFam!F14 -> 4576 | C13: ='Two-par'!F14 -> 0 | D13: ='One-par'!F14 -> 3187 | E13: ='Zero-par'!F14 -> 1389 | F13: =TRec!F14 -> 14581 | G13: =Adults!F14 -> 3187 | H13: =Children!F14 -> 11394
A14: Florida | B14: =TFam!F15 -> 29599 | C14: ='Two-par'!F15 -> 5032 | D14: ='One-par'!F15 -> 6567 | E14: ='Zero-par'!F15 -> 18000 | F14: =TRec!F15 -> 57790 | G14: =Adults!F15 -> 19185 | H14: =Children!F15 -> 38605
A15: Georgia | B15: =TFam!F16 -> 4194 | C15: ='Two-par'!F16 -> 0 | D15: ='One-par'!F16 -> 160 | E15: ='Zero-par'!F16 -> 4034 | F15: =TRec!F16 -> 7277 | G15: =Adults!F16 -> 159 | H15: =Children!F16 -> 7118
... A58: Wyoming | B58: =TFam!F59 -> 476 | C58: ='Two-par'!F59 -> 17 | D58: ='One-par'!F59 -> 249 | E58: ='Zero-par'!F59 -> 210 | F58: =TRec!F59 -> 1184 | G58: =Adults!F59 -> 282 | H58: =Children!F59 -> 902
A59: =TFam!$A$3 -> 45687
A60: ='Oct23'!A60
A61: ='Oct23'!A61 -> Notes:
A62: ='Oct23'!A62 -> "-" - data inapplicable

Sheet Mar24
A1: March 2024
A2: ='Oct23'!$A$2 -> Temporary Assistance for Needy Families (TANF)
A3: State | B3: Total Families | C3: Two Parent Families | D3: One Parent Families | E3: No Parent Families | F3: Total Recipients | G3: Adults | H3: Children
A4: U.S. Totals | B4: =TFam!G5 -> 829625 | C4: ='Two-par'!G5 -> 55607 | D4: ='One-par'!G5 -> 428338 | E4: ='Zero-par'!G5 -> 345680 | F4: =TRec!G5 -> 2028620 | G4: =Adults!G5 -> 549318 | H4: =Children!G5 -> 1479302
A5: Alabama | B5: =TFam!G6 -> 5739 | C5: ='Two-par'!G6 -> 27 | D5: ='One-par'!G6 -> 2393 | E5: ='Zero-par'!G6 -> 3319 | F5: =TRec!G6 -> 13502 | G5: =Adults!G6 -> 2505 | H5: =Children!G6 -> 10997
A6: Alaska | B6: =TFam!G7 -> 1253 | C6: ='Two-par'!G7 -> 155 | D6: ='One-par'!G7 -> 722 | E6: ='Zero-par'!G7 -> 376 | F6: =TRec!G7 -> 3440 | G6: =Adults!G7 -> 1074 | H6: =Children!G7 -> 2366
A7: Arizona | B7: =TFam!G8 -> 5023 | C7: ='Two-par'!G8 -> 351 | D7: ='One-par'!G8 -> 1297 | E7: ='Zero-par'!G8 -> 3375 | F7: =TRec!G8 -> 10525 | G7: =Adults!G8 -> 2022 | H7: =Children!G8 -> 8503
A8: Arkansas | B8: =TFam!G9 -> 954 | C8: ='Two-par'!G9 -> 45 | D8: ='One-par'!G9 -> 538 | E8: ='Zero-par'!G9 -> 371 | F8: =TRec!G9 -> 2366 | G8: =Adults!G9 -> 628 | H8: =Children!G9 -> 1738
A9: California | B9: =TFam!G10 -> 283229 | C9: ='Two-par'!G10 -> 35632 | D9: ='One-par'!G10 -> 149141 | E9: ='Zero-par'!G10 -> 98456 | F9: =TRec!G10 -> 751858 | G9: =Adults!G10 -> 203156 | H9: =Children!G10 -> 548702
A10: Colorado | B10: =TFam!G11 -> 12241 | C10: ='Two-par'!G11 -> 0 | D10: ='One-par'!G11 -> 7958 | E10: ='Zero-par'!G11 -> 4283 | F10: =TRec!G11 -> 29949 | G10: =Adults!G11 -> 8281 | H10: =Children!G11 -> 21668
A11: Connecticut | B11: =TFam!G12 -> 5045 | C11: ='Two-par'!G12 -> 0 | D11: ='One-par'!G12 -> 1940 | E11: ='Zero-par'!G12 -> 3105 | F11: =TRec!G12 -> 11981 | G11: =Adults!G12 -> 3439 | H11: =Children!G12 -> 8542
A12: Delaware | B12: =TFam!G13 -> 2503 | C12: ='Two-par'!G13 -> 3 | D12: ='One-par'!G13 -> 630 | E12: ='Zero-par'!G13 -> 1870 | F12: =TRec!G13 -> 7021 | G12: =Adults!G13 -> 2843 | H12: =Children!G13 -> 4178
A13: District of Columbia | B13: =TFam!G14 -> 4766 | C13: ='Two-par'!G14 -> 0 | D13: ='One-par'!G14 -> 3365 | E13: ='Zero-par'!G14 -> 1401 | F13: =TRec!G14 -> 15299 | G13: =Adults!G14 -> 3365 | H13: =Children!G14 -> 11934
A14: Florida | B14: =TFam!G15 -> 29402 | C14: ='Two-par'!G15 -> 4868 | D14: ='One-par'!G15 -> 6841 | E14: ='Zero-par'!G15 -> 17693 | F14: =TRec!G15 -> 57674 | G14: =Adults!G15 -> 19166 | H14: =Children!G15 -> 38508
A15: Georgia | B15: =TFam!G16 -> 4095 | C15: ='Two-par'!G16 -> 0 | D15: ='One-par'!G16 -> 147 | E15: ='Zero-par'!G16 -> 3948 | F15: =TRec!G16 -> 7128 | G15: =Adults!G16 -> 148 | H15: =Children!G16 -> 6980
... A58: Wyoming | B58: =TFam!G59 -> 467 | C58: ='Two-par'!G59 -> 17 | D58: ='One-par'!G59 -> 239 | E58: ='Zero-par'!G59 -> 211 | F58: =TRec!G59 -> 1153 | G58: =Adults!G59 -> 272 | H58: =Children!G59 -> 881
A59: =TFam!$A$3 -> 45687
A61: Notes:
A62: "-" - data inapplicable

Sheet Apr24
A1: April 2024
A2: ='Oct23'!$A$2 -> Temporary Assistance for Needy Families (TANF)
A3: State | B3: Total Families | C3: Two Parent Families | D3: One Parent Families | E3: No Parent Families | F3: Total Recipients | G3: Adults | H3: Children
A4: U.S. Totals | B4: =TFam!H5 -> 830038 | C4: ='Two-par'!H5 -> 55811 | D4: ='One-par'!H5 -> 429016 | E4: ='Zero-par'!H5 -> 345211 | F4: =TRec!H5 -> 2027090 | G4: =Adults!H5 -> 550073 | H4: =Children!H5 -> 1477017
A5: Alabama | B5: =TFam!H6 -> 5686 | C5: ='Two-par'!H6 -> 29 | D5: ='One-par'!H6 -> 2354 | E5: ='Zero-par'!H6 -> 3303 | F5: =TRec!H6 -> 13314 | G5: =Adults!H6 -> 2464 | H5: =Children!H6 -> 10850
A6: Alaska | B6: =TFam!H7 -> 1345 | C6: ='Two-par'!H7 -> 179 | D6: ='One-par'!H7 -> 787 | E6: ='Zero-par'!H7 -> 379 | F6: =TRec!H7 -> 3719 | G6: =Adults!H7 -> 1190 | H6: =Children!H7 -> 2529
A7: Arizona | B7: =TFam!H8 -> 4930 | C7: ='Two-par'!H8 -> 343 | D7: ='One-par'!H8 -> 1295 | E7: ='Zero-par'!H8 -> 3292 | F7: =TRec!H8 -> 10310 | G7: =Adults!H8 -> 2000 | H7: =Children!H8 -> 8310
A8: Arkansas | B8: =TFam!H9 -> 911 | C8: ='Two-par'!H9 -> 42 | D8: ='One-par'!H9 -> 501 | E8: ='Zero-par'!H9 -> 368 | F8: =TRec!H9 -> 2265 | G8: =Adults!H9 -> 585 | H8: =Children!H9 -> 1680
A9: California | B9: =TFam!H10 -> 282901 | C9: ='Two-par'!H10 -> 35800 | D9: ='One-par'!H10 -> 148668 | E9: ='Zero-par'!H10 -> 98433 | F9: =TRec!H10 -> 749953 | G9: =Adults!H10 -> 202846 | H9: =Children!H10 -> 547107
A10: Colorado | B10: =TFam!H11 -> 12250 | C10: ='Two-par'!H11 -> 0 | D10: ='One-par'!H11 -> 8027 | E10: ='Zero-par'!H11 -> 4223 | F10: =TRec!H11 -> 29950 | G10: =Adults!H11 -> 8308 | H10: =Children!H11 -> 21642
A11: Connecticut | B11: =TFam!H12 -> 5021 | C11: ='Two-par'!H12 -> 0 | D11: ='One-par'!H12 -> 1951 | E11: ='Zero-par'!H12 -> 3070 | F11: =TRec!H12 -> 11956 | G11: =Adults!H12 -> 3435 | H11: =Children!H12 -> 8521
A12: Delaware | B12: =TFam!H13 -> 2460 | C12: ='Two-par'!H13 -> 3 | D12: ='One-par'!H13 -> 593 | E12: ='Zero-par'!H13 -> 1864 | F12: =TRec!H13 -> 6894 | G12: =Adults!H13 -> 2808 | H12: =Children!H13 -> 4086
A13: District of Columbia | B13: =TFam!H14 -> 4694 | C13: ='Two-par'!H14 -> 0 | D13: ='One-par'!H14 -> 3289 | E13: ='Zero-par'!H14 -> 1405 | F13: =TRec!H14 -> 15101 | G13: =Adults!H14 -> 3289 | H13: =Children!H14 -> 11812
A14: Florida | B14: =TFam!H15 -> 29046 | C14: ='Two-par'!H15 -> 4699 | D14: ='One-par'!H15 -> 6966 | E14: ='Zero-par'!H15 -> 17381 | F14: =TRec!H15 -> 57180 | G14: =Adults!H15 -> 19060 | H14: =Children!H15 -> 38120
A15: Georgia | B15: =TFam!H16 -> 4024 | C15: ='Two-par'!H16 -> 0 | D15: ='One-par'!H16 -> 136 | E15: ='Zero-par'!H16 -> 3888 | F15: =TRec!H16 -> 6952 | G15: =Adults!H16 -> 133 | H15: =Children!H16 -> 6819
... A58: Wyoming | B58: =TFam!H59 -> 485 | C58: ='Two-par'!H59 -> 20 | D58: ='One-par'!H59 -> 251 | E58: ='Zero-par'!H59 -> 214 | F58: =TRec!H59 -> 1199 | G58: =Adults!H59 -> 292 | H58: =Children!H59 -> 907
A59: =TFam!$A$3 -> 45687
A60: ='Oct23'!A60
A61: ='Oct23'!A61 -> Notes:
A62: ='Oct23'!A62 -> "-" - data inapplicable

Sheet May24
A1: May 2024
A2: ='Oct23'!$A$2 -> Temporary Assistance for Needy Families (TANF)
A3: State | B3: Total Families | C3: Two Parent Families | D3: One Parent Families | E3: No Parent Families | F3: Total Recipients | G3: Adults | H3: Children
A4: U.S. Totals | B4: =TFam!I5 -> 835567 | C4: ='Two-par'!I5 -> 56278 | D4: ='One-par'!I5 -> 434037 | E4: ='Zero-par'!I5 -> 345252 | F4: =TRec!I5 -> 2050653 | G4: =Adults!I5 -> 559353 | H4: =Children!I5 -> 1491300
A5: Alabama | B5: =TFam!I6 -> 5668 | C5: ='Two-par'!I6 -> 31 | D5: ='One-par'!I6 -> 2353 | E5: ='Zero-par'!I6 -> 3284 | F5: =TRec!I6 -> 13315 | G5: =Adults!I6 -> 2474 | H5: =Children!I6 -> 10841
A6: Alaska | B6: =TFam!I7 -> 1322 | C6: ='Two-par'!I7 -> 174 | D6: ='One-par'!I7 -> 766 | E6: ='Zero-par'!I7 -> 382 | F6: =TRec!I7 -> 3662 | G6: =Adults!I7 -> 1157 | H6: =Children!I7 -> 2505
A7: Arizona | B7: =TFam!I8 -> 4882 | C7: ='Two-par'!I8 -> 358 | D7: ='One-par'!I8 -> 1284 | E7: ='Zero-par'!I8 -> 3240 | F7: =TRec!I8 -> 10244 | G7: =Adults!I8 -> 2023 | H7: =Children!I8 -> 8221
A8: Arkansas | B8: =TFam!I9 -> 879 | C8: ='Two-par'!I9 -> 41 | D8: ='One-par'!I9 -> 488 | E8: ='Zero-par'!I9 -> 350 | F8: =TRec!I9 -> 2182 | G8: =Adults!I9 -> 570 | H8: =Children!I9 -> 1612
A9: California | B9: =TFam!I10 -> 284394 | C9: ='Two-par'!I10 -> 36222 | D9: ='One-par'!I10 -> 149622 | E9: ='Zero-par'!I10 -> 98550 | F9: =TRec!I10 -> 754368 | G9: =Adults!I10 -> 204462 | H9: =Children!I10 -> 549906
A10: Colorado | B10: =TFam!I11 -> 12292 | C10: ='Two-par'!I11 -> 0 | D10: ='One-par'!I11 -> 8090 | E10: ='Zero-par'!I11 -> 4202 | F10: =TRec!I11 -> 29996 | G10: =Adults!I11 -> 8365 | H10: =Children!I11 -> 21631
A11: Connecticut | B11: =TFam!I12 -> 5103 | C11: ='Two-par'!I12 -> 0 | D11: ='One-par'!I12 -> 2058 | E11: ='Zero-par'!I12 -> 3045 | F11: =TRec!I12 -> 12196 | G11: =Adults!I12 -> 3532 | H11: =Children!I12 -> 8664
A12: Delaware | B12: =TFam!I13 -> 2455 | C12: ='Two-par'!I13 -> 4 | D12: ='One-par'!I13 -> 582 | E12: ='Zero-par'!I13 -> 1869 | F12: =TRec!I13 -> 6865 | G12: =Adults!I13 -> 2804 | H12: =Children!I13 -> 4061
A13: District of Columbia | B13: =TFam!I14 -> 4835 | C13: ='Two-par'!I14 -> 0 | D13: ='One-par'!I14 -> 3398 | E13: ='Zero-par'!I14 -> 1437 | F13: =TRec!I14 -> 15525 | G13: =Adults!I14 -> 3398 | H13: =Children!I14 -> 12127
A14: Florida | B14: =TFam!I15 -> 29042 | C14: ='Two-par'!I15 -> 4537 | D14: ='One-par'!I15 -> 7131 | E14: ='Zero-par'!I15 -> 17374 | F14: =TRec!I15 -> 57058 | G14: =Adults!I15 -> 18977 | H14: =Children!I15 -> 38081
A15: Georgia | B15: =TFam!I16 -> 4038 | C15: ='Two-par'!I16 -> 0 | D15: ='One-par'!I16 -> 143 | E15: ='Zero-par'!I16 -> 3895 | F15: =TRec!I16 -> 6972 | G15: =Adults!I16 -> 140 | H15: =Children!I16 -> 6832
... A58: Wyoming | B58: =TFam!I59 -> 482 | C58: ='Two-par'!I59 -> 22 | D58: ='One-par'!I59 -> 246 | E58: ='Zero-par'!I59 -> 214 | F58: =TRec!I59 -> 1195 | G58: =Adults!I59 -> 291 | H58: =Children!I59 -> 904
A59: =TFam!$A$3 -> 45687
A60: ='Oct23'!A60
A61: ='Oct23'!A61 -> Notes:
A62: ='Oct23'!A62 -> "-" - data inapplicable

Sheet Jun24
A1: June 2024
A2: ='Oct23'!$A$2 -> Temporary Assistance for Needy Families (TANF)
A3: State | B3: Total Families | C3: Two Parent Families | D3: One Parent Families | E3: No Parent Families | F3: Total Recipients | G3: Adults | H3: Children
A4: U.S. Totals | B4: =TFam!J5 -> 825495 | C4: ='Two-par'!J5 -> 55055 | D4: ='One-par'!J5 -> 431648 | E4: ='Zero-par'!J5 -> 338792 | F4: =TRec!J5 -> 2017199 | G4: =Adults!J5 -> 551890 | H4: =Children!J5 -> 1465309
A5: Alabama | B5: =TFam!J6 -> 5638 | C5: ='Two-par'!J6 -> 34 | D5: ='One-par'!J6 -> 2373 | E5: ='Zero-par'!J6 -> 3231 | F5: =TRec!J6 -> 13348 | G5: =Adults!J6 -> 2507 | H5: =Children!J6 -> 10841
A6: Alaska | B6: =TFam!J7 -> 1253 | C6: ='Two-par'!J7 -> 155 | D6: ='One-par'!J7 -> 722 | E6: ='Zero-par'!J7 -> 376 | F6: =TRec!J7 -> 3440 | G6: =Adults!J7 -> 1074 | H6: =Children!J7 -> 2366
A7: Arizona | B7: =TFam!J8 -> 4744 | C7: ='Two-par'!J8 -> 359 | D7: ='One-par'!J8 -> 1251 | E7: ='Zero-par'!J8 -> 3134 | F7: =TRec!J8 -> 10076 | G7: =Adults!J8 -> 1996 | H7: =Children!J8 -> 8080
A8: Arkansas | B8: =TFam!J9 -> 838 | C8: ='Two-par'!J9 -> 32 | D8: ='One-par'!J9 -> 470 | E8: ='Zero-par'!J9 -> 336 | F8: =TRec!J9 -> 2046 | G8: =Adults!J9 -> 534 | H8: =Children!J9 -> 1512
A9: California | B9: =TFam!J10 -> 274381 | C9: ='Two-par'!J10 -> 35171 | D9: ='One-par'!J10 -> 144691 | E9: ='Zero-par'!J10 -> 94519 | F9: =TRec!J10 -> 725301 | G9: =Adults!J10 -> 197720 | H9: =Children!J10 -> 527581
A10: Colorado | B10: =TFam!J11 -> 12257 | C10: ='Two-par'!J11 -> 0 | D10: ='One-par'!J11 -> 8145 | E10: ='Zero-par'!J11 -> 4112 | F10: =TRec!J11 -> 30000 | G10: =Adults!J11 -> 8441 | H10: =Children!J11 -> 21559
A11: Connecticut | B11: =TFam!J12 -> 5303 | C11: ='Two-par'!J12 -> 0 | D11: ='One-par'!J12 -> 2211 | E11: ='Zero-par'!J12 -> 3092 | F11: =TRec!J12 -> 12660 | G11: =Adults!J12 -> 3706 | H11: =Children!J12 -> 8954
A12: Delaware | B12: =TFam!J13 -> 2470 | C12: ='Two-par'!J13 -> 5 | D12: ='One-par'!J13 -> 573 | E12: ='Zero-par'!J13 -> 1892 | F12: =TRec!J13 -> 6932 | G12: =Adults!J13 -> 2830 | H12: =Children!J13 -> 4102
A13: District of Columbia | B13: =TFam!J14 -> 4884 | C13: ='Two-par'!J14 -> 0 | D13: ='One-par'!J14 -> 3423 | E13: ='Zero-par'!J14 -> 1461 | F13: =TRec!J14 -> 15727 | G13: =Adults!J14 -> 3423 | H13: =Children!J14 -> 12304
A14: Florida | B14: =TFam!J15 -> 28754 | C14: ='Two-par'!J15 -> 4331 | D14: ='One-par'!J15 -> 7397 | E14: ='Zero-par'!J15 -> 17026 | F14: =TRec!J15 -> 56752 | G14: =Adults!J15 -> 18893 | H14: =Children!J15 -> 37859
A15: Georgia | B15: =TFam!J16 -> 4007 | C15: ='Two-par'!J16 -> 0 | D15: ='One-par'!J16 -> 129 | E15: ='Zero-par'!J16 -> 3878 | F15: =TRec!J16 -> 6894 | G15: =Adults!J16 -> 126 | H15: =Children!J16 -> 6768
... A58: Wyoming | B58: =TFam!J59 -> 491 | C58: ='Two-par'!J59 -> 23 | D58: ='One-par'!J59 -> 252 | E58: ='Zero-par'!J59 -> 216 | F58: =TRec!J59 -> 1210 | G58: =Adults!J59 -> 298 | H58: =Children!J59 -> 912
A59: =TFam!$A$3 -> 45687
A60: ='Oct23'!A60
A61: ='Oct23'!A61 -> Notes:
A62: ='Oct23'!A62 -> "-" - data inapplicable

Sheet Jul24
A1: July 2024
A2: ='Oct23'!$A$2 -> Temporary Assistance for Needy Families (TANF)
A3: State | B3: Total Families | C3: Two Parent Families | D3: One Parent Families | E3: No Parent Families | F3: Total Recipients | G3: Adults | H3: Children
A4: U.S. Totals | B4: =TFam!K5 -> 865103 | C4: ='Two-par'!K5 -> 59572 | D4: ='One-par'!K5 -> 458344 | E4: ='Zero-par'!K5 -> 347187 | F4: =TRec!K5 -> 2125439 | G4: =Adults!K5 -> 583299 | H4: =Children!K5 -> 1542140
A5: Alabama | B5: =TFam!K6 -> 5791 | C5: ='Two-par'!K6 -> 32 | D5: ='One-par'!K6 -> 2471 | E5: ='Zero-par'!K6 -> 3288 | F5: =TRec!K6 -> 13804 | G5: =Adults!K6 -> 2639 | H5: =Children!K6 -> 11165
A6: Alaska | B6: =TFam!K7 -> 1214 | C6: ='Two-par'!K7 -> 154 | D6: ='One-par'!K7 -> 689 | E6: ='Zero-par'!K7 -> 371 | F6: =TRec!K7 -> 3340 | G6: =Adults!K7 -> 1036 | H6: =Children!K7 -> 2304
A7: Arizona | B7: =TFam!K8 -> 4627 | C7: ='Two-par'!K8 -> 341 | D7: ='One-par'!K8 -> 1218 | E7: ='Zero-par'!K8 -> 3068 | F7: =TRec!K8 -> 9806 | G7: =Adults!K8 -> 1928 | H7: =Children!K8 -> 7878
A8: Arkansas | B8: =TFam!K9 -> 788 | C8: ='Two-par'!K9 -> 28 | D8: ='One-par'!K9 -> 432 | E8: ='Zero-par'!K9 -> 328 | F8: =TRec!K9 -> 1902 | G8: =Adults!K9 -> 488 | H8: =Children!K9 -> 1414
A9: California | B9: =TFam!K10 -> 308527 | C9: ='Two-par'!K10 -> 39623 | D9: ='One-par'!K10 -> 165248 | E9: ='Zero-par'!K10 -> 103656 | F9: =TRec!K10 -> 815989 | G9: =Adults!K10 -> 222030 | H9: =Children!K10 -> 593959
A10: Colorado | B10: =TFam!K11 -> 12640 | C10: ='Two-par'!K11 -> 0 | D10: ='One-par'!K11 -> 8490 | E10: ='Zero-par'!K11 -> 4150 | F10: =TRec!K11 -> 31070 | G10: =Adults!K11 -> 8781 | H10: =Children!K11 -> 22289
A11: Connecticut | B11: =TFam!K12 -> 5385 | C11: ='Two-par'!K12 -> 0 | D11: ='One-par'!K12 -> 2300 | E11: ='Zero-par'!K12 -> 3085 | F11: =TRec!K12 -> 12881 | G11: =Adults!K12 -> 3803 | H11: =Children!K12 -> 9078
A12: Delaware | B12: =TFam!K13 -> 2476 | C12: ='Two-par'!K13 -> 6 | D12: ='One-par'!K13 -> 570 | E12: ='Zero-par'!K13 -> 1900 | F12: =TRec!K13 -> 6914 | G12: =Adults!K13 -> 2837 | H12: =Children!K13 -> 4077
A13: District of Columbia | B13: =TFam!K14 -> 6004 | C13: ='Two-par'!K14 -> 0 | D13: ='One-par'!K14 -> 4527 | E13: ='Zero-par'!K14 -> 1477 | F13: =TRec!K14 -> 19321 | G13: =Adults!K14 -> 4527 | H13: =Children!K14 -> 14794
A14: Florida | B14: =TFam!K15 -> 28070 | C14: ='Two-par'!K15 -> 4126 | D14: ='One-par'!K15 -> 7345 | E14: ='Zero-par'!K15 -> 16599 | F14: =TRec!K15 -> 55415 | G14: =Adults!K15 -> 18447 | H14: =Children!K15 -> 36968
A15: Georgia | B15: =TFam!K16 -> 3978 | C15: ='Two-par'!K16 -> 2 | D15: ='One-par'!K16 -> 101 | E15: ='Zero-par'!K16 -> 3875 | F15: =TRec!K16 -> 6861 | G15: =Adults!K16 -> 149 | H15: =Children!K16 -> 6712
... A58: Wyoming | B58: =TFam!K59 -> 486 | C58: ='Two-par'!K59 -> 25 | D58: ='One-par'!K59 -> 248 | E58: ='Zero-par'!K59 -> 213 | F58: =TRec!K59 -> 1197 | G58: =Adults!K59 -> 297 | H58: =Children!K59 -> 900
A59: =TFam!$A$3 -> 45687
A60: ='Oct23'!A60
A61: ='Oct23'!A61 -> Notes:
A62: ='Oct23'!A62 -> "-" - data inapplicable

Sheet Aug24
A1: August 2024
A2: ='Oct23'!$A$2 -> Temporary Assistance for Needy Families (TANF)
A3: State | B3: Total Families | C3: Two Parent Families | D3: One Parent Families | E3: No Parent Families | F3: Total Recipients | G3: Adults | H3: Children
A4: U.S. Totals | B4: =TFam!L5 -> 869951 | C4: ='Two-par'!L5 -> 59666 | D4: ='One-par'!L5 -> 463771 | E4: ='Zero-par'!L5 -> 346514 | F4: =TRec!L5 -> 2140660 | G4: =Adults!L5 -> 588968 | H4: =Children!L5 -> 1551692
A5: Alabama | B5: =TFam!L6 -> 5950 | C5: ='Two-par'!L6 -> 35 | D5: ='One-par'!L6 -> 2612 | E5: ='Zero-par'!L6 -> 3303 | F5: =TRec!L6 -> 14254 | G5: =Adults!L6 -> 2767 | H5: =Children!L6 -> 11487
A6: Alaska | B6: =TFam!L7 -> 1201 | C6: ='Two-par'!L7 -> 167 | D6: ='One-par'!L7 -> 670 | E6: ='Zero-par'!L7 -> 364 | F6: =TRec!L7 -> 3338 | G6: =Adults!L7 -> 1042 | H6: =Children!L7 -> 2296
A7: Arizona | B7: =TFam!L8 -> 4561 | C7: ='Two-par'!L8 -> 318 | D7: ='One-par'!L8 -> 1191 | E7: ='Zero-par'!L8 -> 3052 | F7: =TRec!L8 -> 9652 | G7: =Adults!L8 -> 1853 | H7: =Children!L8 -> 7799
A8: Arkansas | B8: =TFam!L9 -> 738 | C8: ='Two-par'!L9 -> 26 | D8: ='One-par'!L9 -> 386 | E8: ='Zero-par'!L9 -> 326 | F8: =TRec!L9 -> 1759 | G8: =Adults!L9 -> 438 | H8: =Children!L9 -> 1321
A9: California | B9: =TFam!L10 -> 310010 | C9: ='Two-par'!L10 -> 39953 | D9: ='One-par'!L10 -> 166663 | E9: ='Zero-par'!L10 -> 103394 | F9: =TRec!L10 -> 819276 | G9: =Adults!L10 -> 223759 | H9: =Children!L10 -> 595517
A10: Colorado | B10: =TFam!L11 -> 12878 | C10: ='Two-par'!L11 -> 0 | D10: ='One-par'!L11 -> 8740 | E10: ='Zero-par'!L11 -> 4138 | F10: =TRec!L11 -> 31795 | G10: =Adults!L11 -> 8999 | H10: =Children!L11 -> 22796
A11: Connecticut | B11: =TFam!L12 -> 5421 | C11: ='Two-par'!L12 -> 0 | D11: ='One-par'!L12 -> 2358 | E11: ='Zero-par'!L12 -> 3063 | F11: =TRec!L12 -> 13048 | G11: =Adults!L12 -> 3876 | H11: =Children!L12 -> 9172
A12: Delaware | B12: =TFam!L13 -> 2539 | C12: ='Two-par'!L13 -> 6 | D12: ='One-par'!L13 -> 606 | E12: ='Zero-par'!L13 -> 1927 | F12: =TRec!L13 -> 7103 | G12: =Adults!L13 -> 2902 | H12: =Children!L13 -> 4201
A13: District of Columbia | B13: =TFam!L14 -> 5738 | C13: ='Two-par'!L14 -> 0 | D13: ='One-par'!L14 -> 4279 | E13: ='Zero-par'!L14 -> 1459 | F13: =TRec!L14 -> 18316 | G13: =Adults!L14 -> 4279 | H13: =Children!L14 -> 14037
A14: Florida | B14: =TFam!L15 -> 27281 | C14: ='Two-par'!L15 -> 3739 | D14: ='One-par'!L15 -> 7203 | E14: ='Zero-par'!L15 -> 16339 | F14: =TRec!L15 -> 53306 | G14: =Adults!L15 -> 17457 | H14: =Children!L15 -> 35849
A15: Georgia | B15: =TFam!L16 -> 3984 | C15: ='Two-par'!L16 -> 0 | D15: ='One-par'!L16 -> 109 | E15: ='Zero-par'!L16 -> 3875 | F15: =TRec!L16 -> 6891 | G15: =Adults!L16 -> 155 | H15: =Children!L16 -> 6736
... A58: Wyoming | B58: =TFam!L59 -> 490 | C58: ='Two-par'!L59 -> 25 | D58: ='One-par'!L59 -> 255 | E58: ='Zero-par'!L59 -> 210 | F58: =TRec!L59 -> 1216 | G58: =Adults!L59 -> 305 | H58: =Children!L59 -> 911
A59: =TFam!$A$3 -> 45687
A60: ='Oct23'!A60
A61: ='Oct23'!A61 -> Notes:
A62: ='Oct23'!A62 -> "-" - data inapplicable

Sheet Sep24
A1: September 2024
A2: ='Oct23'!$A$2 -> Temporary Assistance for Needy Families (TANF)
A3: State | B3: Total Families | C3: Two Parent Families | D3: One Parent Families | E3: No Parent Families | F3: Total Recipients | G3: Adults | H3: Children
A4: U.S. Totals | B4: =TFam!M5 -> 861564 | C4: ='Two-par'!M5 -> 58459 | D4: ='One-par'!M5 -> 462093 | E4: ='Zero-par'!M5 -> 341012 | F4: =TRec!M5 -> 2118873 | G4: =Adults!M5 -> 585207 | H4: =Children!M5 -> 1533666
A5: Alabama | B5: =TFam!M6 -> 6031 | C5: ='Two-par'!M6 -> 44 | D5: ='One-par'!M6 -> 2722 | E5: ='Zero-par'!M6 -> 3265 | F5: =TRec!M6 -> 14539 | G5: =Adults!M6 -> 2870 | H5: =Children!M6 -> 11669
A6: Alaska | B6: =TFam!M7 -> 1157 | C6: ='Two-par'!M7 -> 156 | D6: ='One-par'!M7 -> 647 | E6: ='Zero-par'!M7 -> 354 | F6: =TRec!M7 -> 3204 | G6: =Adults!M7 -> 996 | H6: =Children!M7 -> 2208
A7: Arizona | B7: =TFam!M8 -> 4430 | C7: ='Two-par'!M8 -> 293 | D7: ='One-par'!M8 -> 1170 | E7: ='Zero-par'!M8 -> 2967 | F7: =TRec!M8 -> 9307 | G7: =Adults!M8 -> 1785 | H7: =Children!M8 -> 7522
A8: Arkansas | B8: =TFam!M9 -> 719 | C8: ='Two-par'!M9 -> 27 | D8: ='One-par'!M9 -> 391 | E8: ='Zero-par'!M9 -> 301 | F8: =TRec!M9 -> 1748 | G8: =Adults!M9 -> 445 | H8: =Children!M9 -> 1303
A9: California | B9: =TFam!M10 -> 299797 | C9: ='Two-par'!M10 -> 38894 | D9: ='One-par'!M10 -> 161793 | E9: ='Zero-par'!M10 -> 99110 | F9: =TRec!M10 -> 790675 | G9: =Adults!M10 -> 217063 | H9: =Children!M10 -> 573612
A10: Colorado | B10: =TFam!M11 -> 13464 | C10: ='Two-par'!M11 -> 0 | D10: ='One-par'!M11 -> 9143 | E10: ='Zero-par'!M11 -> 4321 | F10: =TRec!M11 -> 33199 | G10: =Adults!M11 -> 9406 | H10: =Children!M11 -> 23793
A11: Connecticut | B11: =TFam!M12 -> 5515 | C11: ='Two-par'!M12 -> 0 | D11: ='One-par'!M12 -> 2461 | E11: ='Zero-par'!M12 -> 3054 | F11: =TRec!M12 -> 13303 | G11: =Adults!M12 -> 4001 | H11: =Children!M12 -> 9302
A12: Delaware | B12: =TFam!M13 -> 2541 | C12: ='Two-par'!M13 -> 5 | D12: ='One-par'!M13 -> 604 | E12: ='Zero-par'!M13 -> 1932 | F12: =TRec!M13 -> 7099 | G12: =Adults!M13 -> 2906 | H12: =Children!M13 -> 4193
A13: District of Columbia | B13: =TFam!M14 -> 5274 | C13: ='Two-par'!M14 -> 0 | D13: ='One-par'!M14 -> 3824 | E13: ='Zero-par'!M14 -> 1450 | F13: =TRec!M14 -> 16701 | G13: =Adults!M14 -> 3824 | H13: =Children!M14 -> 12877
A14: Florida | B14: =TFam!M15 -> 27469 | C14: ='Two-par'!M15 -> 3520 | D14: ='One-par'!M15 -> 7598 | E14: ='Zero-par'!M15 -> 16351 | F14: =TRec!M15 -> 53736 | G14: =Adults!M15 -> 17442 | H14: =Children!M15 -> 36294
A15: Georgia | B15: =TFam!M16 -> 3944 | C15: ='Two-par'!M16 -> 0 | D15: ='One-par'!M16 -> 105 | E15: ='Zero-par'!M16 -> 3839 | F15: =TRec!M16 -> 6830 | G15: =Adults!M16 -> 159 | H15: =Children!M16 -> 6671
... A58: Wyoming | B58: =TFam!M59 -> 476 | C58: ='Two-par'!M59 -> 22 | D58: ='One-par'!M59 -> 243 | E58: ='Zero-par'!M59 -> 211 | F58: =TRec!M59 -> 1174 | G58: =Adults!M59 -> 287 | H58: =Children!M59 -> 887
A59: =TFam!$A$3 -> 45687
A60: ='Oct23'!A60
A61: ='Oct23'!A61 -> Notes:
A62: ='Oct23'!A62 -> "-" - data inapplicable

Sheet FYCY2024-Families
C1: 2024
C2: Temporary Assistance for Needy Families (TANF)
C3: AVERAGE MONTHLY NUMBER OF FAMILIES: Oct. 2023 - Sep. 2024
D4: Fiscal Year 2024 (October - September)
C5: State | D5: Total Families | E5: Two Parent Families | F5: One Parent Families | G5: No Parent Families
C6: U.S. Totals | D6: =TFam!N5 -> 841208.67 | E6: ='Two-par'!N5 -> 56430.917 | F6: ='One-par'!N5 -> 438444.92 | G6: ='Zero-par'!N5 -> 346332.83
C7: Alabama | D7: =TFam!N6 -> 5792.9167 | E7: ='Two-par'!N6 -> 33.166667 | F7: ='One-par'!N6 -> 2444 | G7: ='Zero-par'!N6 -> 3315.75
